<?xml version="1.0" encoding="utf-8"?>
<!-- This URDF was automatically created by SolidWorks to URDF Exporter! Originally created by Stephen Brawner (brawner@gmail.com) 
     Commit Version: 1.5.1-0-g916b5db  Build Version: 1.5.7152.31018
     For more information, please see http://wiki.ros.org/sw_urdf_exporter -->
<robot
  name="motorcycle_description">
  <link
    name="base_link">
    <inertial>
      <origin
        xyz="0.000168258710634461 2.77555756156289E-17 0.000666685304828721"
        rpy="0 0 0" />
      <mass
        value="0289701.940057169" />
      <inertia
        ixx="0000253.455095870824"
        ixy="-3647126.16334703E-20"
        ixz="-6252751.07183654E-05"
        iyy="0000310.482942954787"
        iyz="1460778.59887043E-20"
        izz="0000361.408262602352" />
    </inertial>
    <visual>
      <origin
        xyz="0 0 0"
        rpy="0 0 0" />
      <geometry>
        <mesh
          filename="package://motorcycle_description/meshes/base_link.STL" />
      </geometry>
      <material
        name="">
        <color
          rgba="0.792156862745098 0.819607843137255 0.933333333333333 1" />
      </material>
    </visual>
    <collision>
      <origin
        xyz="0 0 0"
        rpy="0 0 0" />
      <geometry>
        <mesh
          filename="package://motorcycle_description/meshes/base_link.STL" />
      </geometry>
    </collision>
  </link>
  <link
    name="wheel_front_link">
    <inertial>
      <origin
        xyz="-6.93889390390723E-18 0 0"
        rpy="0 0 0" />
      <mass
        value="0004712.38898038469" />
      <inertia
        ixx="3043417.88316512E-07"
        ixy="2055550.92175828E-38"
        ixz="-1499759.78266185E-40"
        iyy="2945243.11274043E-07"
        iyz="1517756.9000538E-39"
        izz="3043417.88316512E-07" />
    </inertial>
    <visual>
      <origin
        xyz="0 0 0"
        rpy="0 0 0" />
      <geometry>
        <mesh
          filename="package://motorcycle_description/meshes/wheel_front_link.STL" />
      </geometry>
      <material
        name="">
        <color
          rgba="0.792156862745098 0.819607843137255 0.933333333333333 1" />
      </material>
    </visual>
    <collision>
      <origin
        xyz="0 0 0"
        rpy="0 0 0" />
      <geometry>
        <mesh
          filename="package://motorcycle_description/meshes/wheel_front_link.STL" />
      </geometry>
    </collision>
  </link>
  <joint
    name="wheel_front_joint"
    type="continuous">
    <origin
      xyz="0.037828 0 -0.020493"
      rpy="0 0 0" />
    <parent
      link="base_link" />
    <child
      link="wheel_front_link" />
    <axis
      xyz="0 1 0" />
    <dynamics
      damping="0.7" />
  </joint>
  <link
    name="wheel_back_link">
    <inertial>
      <origin
        xyz="6.93889390390723E-18 -1.38777878078145E-17 0"
        rpy="0 0 0" />
      <mass
        value="0004712.38898038469" />
      <inertia
        ixx="3043417.88316512E-07"
        ixy="2055550.92175828E-38"
        ixz="-1499759.78266185E-40"
        iyy="2945243.11274043E-07"
        iyz="1517756.9000538E-39"
        izz="3043417.88316512E-07" />
    </inertial>
    <visual>
      <origin
        xyz="0 0 0"
        rpy="0 0 0" />
      <geometry>
        <mesh
          filename="package://motorcycle_description/meshes/wheel_back_link.STL" />
      </geometry>
      <material
        name="">
        <color
          rgba="0.792156862745098 0.819607843137255 0.933333333333333 1" />
      </material>
    </visual>
    <collision>
      <origin
        xyz="0 0 0"
        rpy="0 0 0" />
      <geometry>
        <mesh
          filename="package://motorcycle_description/meshes/wheel_back_link.STL" />
      </geometry>
    </collision>
  </link>
  <joint
    name="wheel_back_joint"
    type="continuous">
    <origin
      xyz="-0.048172 0 -0.020493"
      rpy="0 0 0" />
    <parent
      link="base_link" />
    <child
      link="wheel_back_link" />
    <axis
      xyz="0 1 0" />
    <dynamics
      damping="0.7" />
  </joint>

  <gazebo
     reference="base_link">
    <mu1>10</mu1>
    <mu2>10</mu2>
    <material>Gazebo/Orange</material>
  </gazebo>
  <gazebo
     reference="wheel_front_link">
    <mu1>10</mu1>
    <mu2>10</mu2>
    <material>Gazebo/Black</material>
  </gazebo>
  <gazebo
     reference="wheel_back_link">
    <mu1>10</mu1>
    <mu2>10</mu2>
    <material>Gazebo/Black</material>
  </gazebo>

  <gazebo>
    <plugin name="gazebo_ros_control" filename="libgazebo_ros_control.so">
      <robotNamespace>/motorcycle</robotNamespace>
      <robotSimType>gazebo_ros_control/DefaultRobotHWSim</robotSimType>
      <legacyModeNS>true</legacyModeNS>
    </plugin>
  </gazebo>

  <transmission name="tran1">
    <type>transmission_interface/SimpleTransmission</type>
    <joint name="wheel_front_joint">
      <hardwareInterface>hardware_interface/EffortJointInterface</hardwareInterface>
    </joint>
    <actuator name="motor1">
      <hardwareInterface>hardware_interface/EffortJointInterface</hardwareInterface>
      <mechanicalReduction>1</mechanicalReduction>
    </actuator>
  </transmission>

  <transmission name="tran2">
    <type>transmission_interface/SimpleTransmission</type>
    <joint name="wheel_back_joint">
      <hardwareInterface>hardware_interface/EffortJointInterface</hardwareInterface>
    </joint>
    <actuator name="motor2">
      <hardwareInterface>hardware_interface/EffortJointInterface</hardwareInterface>
      <mechanicalReduction>1</mechanicalReduction>
    </actuator>
  </transmission>

</robot>

  