<?xml version="1.0" encoding="utf-8"?>
<!-- This URDF was automatically created by SolidWorks to URDF Exporter! Originally created by Stephen Brawner (brawner@gmail.com) 
     Commit Version: 1.6.0-1-g15f4949  Build Version: 1.6.7594.29634
     For more information, please see http://wiki.ros.org/sw_urdf_exporter -->
<robot name="motorcycle_description">
  <link name="Body_Link">
    <inertial>
      <origin xyz="-0.0457307267180003 0.000365145415786028 -0.0589187011884054" rpy="0 0 0" />
      <mass value="45" />
      <inertia ixx="002.02346349576474" ixy="-467.445491686321E-05" ixz="000.835935390031763" iyy="006.09151666273547" iyz="-145.35813974047E-05" izz="006.53262068969237" />
    </inertial>
    <visual>
      <origin xyz="0 0 0" rpy="0 0 0" />
      <geometry>
        <mesh filename="package://motorcycle_description/meshes/Body_Link.STL" />
      </geometry>
      <material name="">
        <color rgba="0.792156862745098 0.819607843137255 0.933333333333333 1" />
      </material>
    </visual>
    <collision>
      <origin xyz="0 0 0" rpy="0 0 0" />
      <geometry>
        <mesh filename="package://motorcycle_description/meshes/Body_Link.STL" />
      </geometry>
    </collision>
  </link>
  <link name="Bwheel_Link">
    <inertial>
      <origin xyz="-8.15629473827073E-06 -6.00897998026539E-09 4.46091212635835E-06" rpy="0 0 0" />
      <mass value="5" />
      <inertia ixx="000.710679469347714" ixy="-516.392714799496E-08" ixz="-613.884077825968E-08" iyy="001.36405161462466" iyz="318.400599978213E-08" izz="000.710707233974415" />
    </inertial>
    <visual>
      <origin xyz="0 0 0" rpy="0 0 0" />
      <geometry>
        <mesh filename="package://motorcycle_description/meshes/Bwheel_Link.STL" />
      </geometry>
      <material name="">
        <color rgba="0.792156862745098 0.819607843137255 0.933333333333333 1" />
      </material>
    </visual>
    <collision>
      <origin xyz="0 0 0" rpy="0 0 0" />
      <geometry>
        <mesh filename="package://motorcycle_description/meshes/Bwheel_Link.STL" />
      </geometry>
    </collision>
  </link>
  <joint name="Bwheel_Joint" type="continuous">
    <origin xyz="-0.34348 0 -0.079568" rpy="0 0 0" />
    <parent link="Body_Link" />
    <child link="Bwheel_Link" />
    <axis xyz="0 1 0" />
    <dynamics damping="0.0" friction="0.7" />
  </joint>
  <link name="Direction_Link">
    <inertial>
      <origin xyz="-0.166474781300737 -0.000119263857456087 0.281677589005923" rpy="0 0 0" />
      <mass value="45" />
      <inertia ixx="000.48183824249781" ixy="295.781610845726E-05" ixz="000.0233761603315691" iyy="000.0716769510720634" iyz="157.761186134796E-05" izz="000.451925784703187" />
    </inertial>
    <visual>
      <origin xyz="0 0 0" rpy="0 0 0" />
      <geometry>
        <mesh filename="package://motorcycle_description/meshes/Direction_Link.STL" />
      </geometry>
      <material name="">
        <color rgba="0.792156862745098 0.819607843137255 0.933333333333333 1" />
      </material>
    </visual>
    <collision>
      <origin xyz="0 0 0" rpy="0 0 0" />
      <geometry>
        <mesh filename="package://motorcycle_description/meshes/Direction_Link.STL" />
      </geometry>
    </collision>
  </link>
  <joint name="FrontFork_Joint" type="revolute">
    <origin xyz="0.37974 9.9046E-05 0.018665" rpy="0 0 0" />
    <parent link="Body_Link" />
    <child link="Direction_Link" />
    <axis xyz="0.46947 0 -0.88295" />
    <limit lower="${-45*pi/180}" upper="${45*pi/180}" effort="10000000000" velocity="10000000000" />
    <dynamics damping="1000.0" friction="0.0" />
  </joint>
  <link name="Fwheel_Link">
    <inertial>
      <origin xyz="-7.20173011448111E-06 -7.57340004042817E-08 -5.86105189182007E-06" rpy="0 0 0" />
      <mass value="5" />
      <inertia ixx="000.710739669025681" ixy="-457.572074141143E-05" ixz="117.048634697159E-07" iyy="001.36401059071135" iyz="-243.406171991038E-05" izz="000.710688249191573" />
    </inertial>
    <visual>
      <origin xyz="0 0 0" rpy="0 0 0" />
      <geometry>
        <mesh filename="package://motorcycle_description/meshes/Fwheel_Link.STL" />
      </geometry>
      <material name="">
        <color rgba="0.792156862745098 0.819607843137255 0.933333333333333 1" />
      </material>
    </visual>
    <collision>
      <origin xyz="0 0 0" rpy="0 0 0" />
      <geometry>
        <mesh filename="package://motorcycle_description/meshes/Fwheel_Link.STL" />
      </geometry>
    </collision>
  </link>
  <joint name="Fwheel_Joint" type="continuous">
    <origin xyz="0.037443 -9.9046E-05 -0.097045" rpy="0 0 0" />
    <parent link="Direction_Link" />
    <child link="Fwheel_Link" />
    <axis xyz="0.0069962 0.99997 0.00372" />
    <dynamics damping="0.0" friction="0.7" />
  </joint>

  <gazebo reference="Body_Link">
    <material>Gazebo/Orange</material>
    <mu1>0.01</mu1>
    <mu2>0.01</mu2>
    <gravity>true</gravity>
    <sensor name="imu_sensor" type="imu">
      <always_on>true</always_on>
      <update_rate>10000</update_rate>
      <visualize>true</visualize>
      <topic>__default_topic__</topic>
      <plugin filename="libgazebo_ros_imu_sensor.so" name="imu_plugin">
        <topicName>imu</topicName>
        <bodyName>imu_link</bodyName>
        <updateRateHZ>10000.0</updateRateHZ>
        <gaussianNoise>0.0</gaussianNoise>
        <xyzOffset>0 0 0</xyzOffset>
        <rpyOffset>0 0 0</rpyOffset>
        <frameName>imu_link</frameName>
        <initialOrientationAsReference>false</initialOrientationAsReference>
      </plugin>
      <pose>0 0 0 0 0 0</pose>
    </sensor>
  </gazebo>
  <gazebo reference="Direction_Link">
    <material>Gazebo/white</material>
    <mu1>0.01</mu1>
    <mu2>0.01</mu2>
  </gazebo>
  <gazebo reference="Fwheel_Link">
    <mu1>10.0</mu1>
    <mu2>10.0</mu2>
    <material>Gazebo/Black</material>
  </gazebo>
  <gazebo reference="Bwheel_Link">
    <mu1>10.0</mu1>
    <mu2>10.0</mu2>
    <material>Gazebo/Black</material>
  </gazebo>

  <gazebo>
    <plugin name="gazebo_ros_control" filename="libgazebo_ros_control.so">
      <robotNamespace>/motorcycle</robotNamespace>
      <robotSimType>gazebo_ros_control/DefaultRobotHWSim</robotSimType>
      <legacyModeNS>true</legacyModeNS>
    </plugin>
  </gazebo>

  <transmission name="FrontFork_Joint_transmission">
    <type>transmission_interface/SimpleTransmission</type>
    <joint name="FrontFork_Joint">
      <hardwareInterface>hardware_interface/EffortJointInterface</hardwareInterface>
    </joint>
    <actuator name="FrontFork_Joint">
      <hardwareInterface>hardware_interface/EffortJointInterface</hardwareInterface>
      <mechanicalReduction>1</mechanicalReduction>
    </actuator>
  </transmission>

  <transmission name="Fwheel_Joint_transmission">
    <type>transmission_interface/SimpleTransmission</type>
    <joint name="Fwheel_Joint">
      <hardwareInterface>hardware_interface/EffortJointInterface</hardwareInterface>
    </joint>
    <actuator name="Fwheel_Joint">
      <hardwareInterface>hardware_interface/EffortJointInterface</hardwareInterface>
      <mechanicalReduction>1</mechanicalReduction>
    </actuator>
  </transmission>

  <transmission name="Bwheel_Joint_transmission">
    <type>transmission_interface/SimpleTransmission</type>
    <joint name="Bwheel_Joint">
      <hardwareInterface>hardware_interface/EffortJointInterface</hardwareInterface>
    </joint>
    <actuator name="Bwheel_Joint">
      <hardwareInterface>hardware_interface/EffortJointInterface</hardwareInterface>
      <mechanicalReduction>1</mechanicalReduction>
    </actuator>
  </transmission>
</robot>