<?xml version="1.0" encoding="utf-8"?>
<!-- This URDF was automatically created by SolidWorks to URDF Exporter! Originally created by Stephen Brawner (brawner@gmail.com) 
     Commit Version: 1.6.0-1-g15f4949  Build Version: 1.6.7594.29634
     For more information, please see http://wiki.ros.org/sw_urdf_exporter -->
<robot
  name="motorcycle_description">
  <link
    name="base_link">
    <inertial>
      <origin
        xyz="0.0198751367056354 0 -0.00661418578080362"
        rpy="0 0 0" />
      <mass
        value="0286167.648321881" />
      <inertia
        ixx="0000251.584686193874"
        ixy="-3992708.85719828E-20"
        ixz="-6499685.59641092E-05"
        iyy="0000303.937337408151"
        iyz="1662968.88374662E-20"
        izz="0000355.890399953188" />
    </inertial>
    <visual>
      <origin
        xyz="0 0 0"
        rpy="0 0 0" />
      <geometry>
        <mesh
          filename="package://motorcycle_description/meshes/base_link.STL" />
      </geometry>
      <material
        name="">
        <color
          rgba="0.792156862745098 0.819607843137255 0.933333333333333 1" />
      </material>
    </visual>
    <collision>
      <origin
        xyz="0 0 0"
        rpy="0 0 0" />
      <geometry>
        <mesh
          filename="package://motorcycle_description/meshes/base_link.STL" />
      </geometry>
    </collision>
  </link>
  <link
    name="wheel_back_link">
    <inertial>
      <origin
        xyz="0 -1.38777878078145E-17 0"
        rpy="0 0 0" />
      <mass
        value="0004712.38898038469" />
      <inertia
        ixx="3043417.88316512E-07"
        ixy="2055550.92175828E-38"
        ixz="-1499759.78266185E-40"
        iyy="2945243.11274043E-07"
        iyz="1517756.9000538E-39"
        izz="3043417.88316512E-07" />
    </inertial>
    <visual>
      <origin
        xyz="0 0 0"
        rpy="0 0 0" />
      <geometry>
        <mesh
          filename="package://motorcycle_description/meshes/wheel_back_link.STL" />
      </geometry>
      <material
        name="">
        <color
          rgba="0.792156862745098 0.819607843137255 0.933333333333333 1" />
      </material>
    </visual>
    <collision>
      <origin
        xyz="0 0 0"
        rpy="0 0 0" />
      <geometry>
        <mesh
          filename="package://motorcycle_description/meshes/wheel_back_link.STL" />
      </geometry>
    </collision>
  </link>
  <joint
    name="wheel_back_joint"
    type="continuous">
    <origin
      xyz="-0.028 0 -0.028"
      rpy="0 0 0" />
    <parent
      link="base_link" />
    <child
      link="wheel_back_link" />
    <axis
      xyz="0 1 0" />
    <dynamics
      damping="0.7" />
  </joint>
  <link
    name="direction_link">
    <inertial>
      <origin
        xyz="-2.27964679445219E-06 5.73904965217586E-10 -0.00713129945231977"
        rpy="0 0 0" />
      <mass
        value="0006154.7356109696" />
      <inertia
        ixx="1053694.07445207E-06"
        ixy="-1101743.23325191E-10"
        ixz="6149286.21383257E-11"
        iyy="6160631.97167564E-07"
        iyz="-1548093.25015491E-14"
        izz="5300653.88397654E-07" />
    </inertial>
    <visual>
      <origin
        xyz="0 0 0"
        rpy="0 0 0" />
      <geometry>
        <mesh
          filename="package://motorcycle_description/meshes/direction_link.STL" />
      </geometry>
      <material
        name="">
        <color
          rgba="0.792156862745098 0.819607843137255 0.933333333333333 1" />
      </material>
    </visual>
    <collision>
      <origin
        xyz="0 0 0"
        rpy="0 0 0" />
      <geometry>
        <mesh
          filename="package://motorcycle_description/meshes/direction_link.STL" />
      </geometry>
    </collision>
  </link>
  <joint
    name="direction_joint"
    type="revolute">
    <origin
      xyz="0.058 0 -0.01"
      rpy="0 0 -0.033503" />
    <parent
      link="base_link" />
    <child
      link="direction_link" />
    <axis
      xyz="0 0 -1" />
    <limit
      lower="-0.5235"
      upper="0.5235"
      effort="0"
      velocity="0" />
    <dynamics
      damping="0.7" />
  </joint>
  <link
    name="wheel_front_link">
    <inertial>
      <origin
        xyz="6.93889390390723E-18 2.77555756156289E-17 3.46944695195361E-18"
        rpy="0 0 0" />
      <mass
        value="0004712.38898038469" />
      <inertia
        ixx="3043306.06945092E-07"
        ixy="-3311311.43430513E-10"
        ixz="-4341140.43296837E-39"
        iyy="2945354.92645463E-07"
        iyz="7353834.97457319E-39"
        izz="3043417.88316512E-07" />
    </inertial>
    <visual>
      <origin
        xyz="0 0 0"
        rpy="0 0 0" />
      <geometry>
        <mesh
          filename="package://motorcycle_description/meshes/wheel_front_link.STL" />
      </geometry>
      <material
        name="">
        <color
          rgba="0.792156862745098 0.819607843137255 0.933333333333333 1" />
      </material>
    </visual>
    <collision>
      <origin
        xyz="0 0 0"
        rpy="0 0 0" />
      <geometry>
        <mesh
          filename="package://motorcycle_description/meshes/wheel_front_link.STL" />
      </geometry>
    </collision>
  </link>
  <joint
    name="wheel_front_joint"
    type="continuous">
    <origin
      xyz="0 0 -0.018"
      rpy="0 0 0.033503" />
    <parent
      link="direction_link" />
    <child
      link="wheel_front_link" />
    <axis
      xyz="-0.033748 -0.99943 0" />
    <dynamics
      damping="0.7" />
  </joint>

  <gazebo
     reference="base_link">
    <mu1>10</mu1>
    <mu2>10</mu2>
    <material>Gazebo/Orange</material>
  </gazebo>
  <gazebo
     reference="direction_link">
    <mu1>10</mu1>
    <mu2>10</mu2>
    <material>Gazebo/blue</material>
  </gazebo>
  <gazebo
     reference="wheel_front_link">
    <mu1>0.1</mu1>
    <mu2>0.1</mu2>
    <material>Gazebo/Black</material>
  </gazebo>
  <gazebo
     reference="wheel_back_link">
    <mu1>10</mu1>
    <mu2>10</mu2>
    <material>Gazebo/Black</material>
  </gazebo>

  <gazebo>
    <plugin name="gazebo_ros_control" filename="libgazebo_ros_control.so">
      <robotNamespace>/motorcycle</robotNamespace>
      <robotSimType>gazebo_ros_control/DefaultRobotHWSim</robotSimType>
      <legacyModeNS>true</legacyModeNS>
    </plugin>
  </gazebo>

  <transmission name="tran1">
    <type>transmission_interface/SimpleTransmission</type>
    <joint name="wheel_front_joint">
      <hardwareInterface>hardware_interface/EffortJointInterface</hardwareInterface>
    </joint>
    <actuator name="motor1">
      <hardwareInterface>hardware_interface/EffortJointInterface</hardwareInterface>
      <mechanicalReduction>1</mechanicalReduction>
    </actuator>
  </transmission>

  <transmission name="tran2">
    <type>transmission_interface/SimpleTransmission</type>
    <joint name="wheel_back_joint">
      <hardwareInterface>hardware_interface/EffortJointInterface</hardwareInterface>
    </joint>
    <actuator name="motor2">
      <hardwareInterface>hardware_interface/EffortJointInterface</hardwareInterface>
      <mechanicalReduction>1</mechanicalReduction>
    </actuator>
  </transmission>

  <transmission name="tran3">
    <type>transmission_interface/SimpleTransmission</type>
    <joint name="direction_joint">
      <hardwareInterface>hardware_interface/EffortJointInterface</hardwareInterface>
    </joint>
    <actuator name="motor3">
      <hardwareInterface>hardware_interface/EffortJointInterface</hardwareInterface>
      <mechanicalReduction>1</mechanicalReduction>
    </actuator>
  </transmission>

</robot>